Workbook
Name chegirma_summa: Buyurtma!$D$16
Name chest_D: Sozlamalar!$C$74
Name chest_Dk: Sozlamalar!$C$117
Name chest_fasH: Sozlamalar!$C$119
Name chest_fasW: Sozlamalar!$C$118
Name chest_H: Sozlamalar!$C$75
Name chest_kra: Sozlamalar!$C$144
Name chest_kyon: Sozlamalar!$C$146
Name chest_kyuz: Sozlamalar!$C$145
Name chest_naprav: Sozlamalar!$C$122
Name chest_qH: Sozlamalar!$C$121
Name chest_qW: Sozlamalar!$C$120
Name chest_soni: Sozlamalar!$C$72
Name chest_W: Sozlamalar!$C$73
Name chest_yashik: Sozlamalar!$C$76
Name dsp_L: Sozlamalar!$C$97
Name dsp_W: Sozlamalar!$C$98
Name dvp_L: Sozlamalar!$C$37
Name dvp_W: Sozlamalar!$C$38
Name emal_norma: Sozlamalar!$C$92
Name eritgich_norma: Sozlamalar!$C$95
Name fasad_tomon: Sozlamalar!$C$89
Name figura_H: Sozlamalar!$C$59
Name figura_koef: Sozlamalar!$C$61
Name figura_qatlam: Sozlamalar!$C$60
Name figura_W: Sozlamalar!$C$58
Name grunt_norma: Sozlamalar!$C$91
Name jami_sotuv: Buyurtma!$E$14
Name k_bolim_eni: Sozlamalar!$C$155
Name k_kupe_eni: Sozlamalar!$C$156
Name k_kupe_H: Sozlamalar!$C$154
Name k_kupe_ustma: Sozlamalar!$C$153
Name k_kupe_zazor: Sozlamalar!$C$152
Name k_oyna_chet: Sozlamalar!$C$159
Name k_yashik_fas: Sozlamalar!$C$157
Name k_yashik_quti: Sozlamalar!$C$158
Name kompaniya_kontakt: Sozlamalar!$C$14
Name kompaniya_nomi: Sozlamalar!$C$13
Name kor_miss: 'Korpus hisob'!$I$92
Name kor_sotuv: 'Korpus hisob'!$I$91
Name kor_tan: 'Korpus hisob'!$I$89
Name korpus_tomon: Sozlamalar!$C$90
Name krovat_balka: Sozlamalar!$C$57
Name krovat_fig: Sozlamalar!$C$54
Name krovat_H: Sozlamalar!$C$52
Name krovat_ichL: Sozlamalar!$C$109
Name krovat_ichW: Sozlamalar!$C$110
Name krovat_L: Sozlamalar!$C$50
Name krovat_nasos: Sozlamalar!$C$55
Name krovat_soni: Sozlamalar!$C$49
Name krovat_spinka: Sozlamalar!$C$53
Name krovat_tsarga: Sozlamalar!$C$56
Name krovat_W: Sozlamalar!$C$51
Name kurs_baza: Sozlamalar!$C$7
Name kurs_joriy: Sozlamalar!$C$8
Name lak_norma: Sozlamalar!$C$93
Name ldsp_L: Sozlamalar!$C$35
Name ldsp_W: Sozlamalar!$C$36
Name mdf_L: Sozlamalar!$C$87
Name mdf_W: Sozlamalar!$C$88

Sheet Buyurtma
A1: Buyurtma — mebel narx kalkulyatori
A2: 1) Mijoz ma'lumotlarini yozing. 2) Buyurtmaga kiradigan bo'limni "Ha" qiling va o'sha varaqda o'lchamlarni kiriting. 3) To'lov shartini tanlang. 4) "Mijoz uchun" varag'ini A4 ga chop eting.
A4: Mijoz F.I.O.
A5: Telefon
A6: Sana | B6: =TODAY() -> 46314 | C6: Bugungi sana avtomatik; kerak bo'lsa o'zgartiring
A7: Filial
A8: Sotuvchi (xodim)
A10: Bo'lim | B10: Buyurtmada bormi? | C10: Varaq | D10: Tan narx (so'm) | E10: Sotuv narxi, naqd (so'm) | F10: Baraka ustamasi (so'm) | G10: Ogohlantirish
A11: Spalniy garnitur | B11: Ha | C11: Spalniy | D11: =IF(p_m_spalniy="Ha",sp_tan,0) -> 9655516.5 | E11: =IF(p_m_spalniy="Ha",sp_sotuv,0) -> 9660000 | F11: =E11-D11 -> 4483.5249 | G11: =IF(p_m_spalniy="Ha",IF(OR(Tannarx!B31>0,AND(Tannarx!B32>0,Tannarx!B33=1),usta_foiz=0,savdo_ustama=0),"Spalniy varag'ini ko'ring",""),"") -> Spalniy varag'ini ko'ring
A12: Oshxona mebeli (pogon metr) | B12: Yo'q | C12: Oshxona | D12: =IF(p_m_oshxona="Ha",osh_tan,0) -> 0 | E12: =IF(p_m_oshxona="Ha",osh_sotuv,0) -> 0 | F12: =E12-D12 -> 0 | G12: =IF(p_m_oshxona="Ha",IF(OR(COUNTIF(Oshxona!G5:G10,"")-COUNTIF(Oshxona!B5:B10,"")>0,AND(LEFT(oshxona_narx_turi,3)="Tan",ustama_oshxona=0)),"Oshxona varag'ini ko'ring",""),"")
A13: Korpus mebel (shkaf, prixojka, garderob) | B13: Yo'q | C13: Korpus mebel | D13: =IF(p_m_korpus="Ha",kor_tan,0) -> 0 | E13: =IF(p_m_korpus="Ha",kor_sotuv,0) -> 0 | F13: =E13-D13 -> 0 | G13: =IF(p_m_korpus="Ha",IF(OR(kor_miss>0,usta_foiz_k=0,ustama_korpus=0),"Korpus mebel varag'ini ko'ring",""),"")
A14: JAMI | D14: =SUM(D11:D13) -> 9655516.5 | E14: =SUM(E11:E13) -> 9660000 | F14: =SUM(F11:F13) -> 4483.5249
A16: Chegirma, % (ixtiyoriy) | B16: 0 | C16: Chegirma summasi: | D16: =ROUND(jami_sotuv*N(p_chegirma)/yaxlit,0)*yaxlit -> 0
A17: NAQD NARX (chegirma bilan) | B17: =jami_sotuv-chegirma_summa -> 9660000
A19: TO'LOV SHARTI
A20: To'lov turi | B20: Naqd | C20: =IF(tanlangan_oy=0,"Naqd savdo","Oylik ustama: "&TEXT(tanlangan_stavka,"0.0%")&" × "&tanlangan_oy&" oy") -> Naqd savdo
A21: Oldindan to'lov, % (masalan 20%) | B21: 0 | C21: ="Oldindan to'lov: "&TEXT(old_tolov,"#,##0")&" so'm ("&TEXT(old_ulush,"0.0%")&")" -> #VALUE!
A22: Oldindan to'lov, so'm (ixtiyoriy — yozilsa, % o'rniga shu olinadi)
A24: To'lov turi | B24: Oylik ustama | C24: Oy | D24: Oylik to'lov (so'm) | E24: Ustama summasi (so'm) | F24: Naqddan farq (so'm) | G24: Jami to'lov (so'm)
A25: =Tariflar!A38 -> Naqd | B25: =Tariflar!C38 -> 0 | C25: =Tariflar!B38 -> 0 | D25: =Tariflar!E38 -> 0 | E25: =Tariflar!D38 -> 0 | F25: =Tariflar!G38 -> 0 | G25: =Tariflar!F38 -> 9660000
A26: =Tariflar!A39 -> 3 oy | B26: =Tariflar!C39 -> 0.05 | C26: =Tariflar!B39 -> 3 | D26: =Tariflar!E39 -> 3703000 | E26: =Tariflar!D39 -> 1449000 | F26: =Tariflar!G39 -> 1449000 | G26: =Tariflar!F39 -> 11109000
A27: =Tariflar!A40 -> 6 oy | B27: =Tariflar!C40 -> 0.04 | C27: =Tariflar!B40 -> 6 | D27: =Tariflar!E40 -> 1997000 | E27: =Tariflar!D40 -> 2318400 | F27: =Tariflar!G40 -> 2322000 | G27: =Tariflar!F40 -> 11982000
A28: =Tariflar!A41 -> 12 oy | B28: =Tariflar!C41 -> 0.035 | C28: =Tariflar!B41 -> 12 | D28: =Tariflar!E41 -> 1144000 | E28: =Tariflar!D41 -> 4057200 | F28: =Tariflar!G41 -> 4068000 | G28: =Tariflar!F41 -> 13728000
A29: =Tariflar!A42 -> 18 oy | B29: =Tariflar!C42 -> 0.033 | C29: =Tariflar!B42 -> 18 | D29: =Tariflar!E42 -> 856000 | E29: =Tariflar!D42 -> 5738040 | F29: =Tariflar!G42 -> 5748000 | G29: =Tariflar!F42 -> 15408000
A31: =IF(royxat_soni>16,"Diqqat: mijoz varag'iga "&royxat_soni&" qator to'g'ri keladi, faqat 16 tasi sig'adi","")
A32: =IF(jami_sotuv=0,"Buyurtmada hali mahsulot yo'q: bo'limni ""Ha"" qiling va o'lchamlarni kiriting","")
A33: Mijozga berish: "Mijoz uchun" varag'ini A4 ga chop eting (tanlangan to'lov turi yashil bilan belgilanadi).

Sheet Spalniy
A1: Spalniy garnitur — hisoblash
A2: Mijozdan olingan o'lchamlarni sariq kataklarga kiriting. Kerak bo'lmagan mahsulot sonini 0 qiling. Mijoz ma'lumotlari va to'lov sharti — "Buyurtma" varag'ida.
A4: Mahsulot | B4: Ko'rsatkich | C4: Qiymat | D4: Birlik | E4: Eslatma
A5: Shkaf | B5: Shkaf soni | C5: 1 | D5: dona
A6: Shkaf | B6: Balandligi (buyi) | C6: 220 | D6: sm
A7: Shkaf | B7: Chuqurligi (eni) | C7: 60 | D7: sm
A8: Shkaf | B8: Uzunligi | C8: 240 | D8: sm | E8: =IF(shkaf_qop_n>1,"Qopqoq "&shkaf_qop_n&" bo'lakdan bo'ladi","")
A9: Shkaf | B9: Eshiklar soni | C9: 6 | D9: dona | E9: ="1 eshik eni: "&ROUND(shkaf_eshikW/10,1)&" sm" -> 1 eshik eni: 39,7 sm
A10: Shkaf | B10: Eshiklardagi oynalar soni | C10: 2 | D10: dona | E10: =IF(shkaf_oyna_soni>shkaf_eshik,"Diqqat: oynalar eshiklardan ko'p",IF(AND(shkaf_oyna_soni>0,shkaf_oyna_W>shkaf_eshikW),"Diqqat: oyna eni ("&shkaf_oyna_W/10&" sm) eshikdan keng — Sozlamalarda tekshiring","Oyna: "&shkaf_oyna_H/10&"×"&shkaf_oyna_W/10&" sm")) -> Diqqat: oyna eni (50 sm) eshikdan keng — Sozlamalarda tekshiring
A11: Shkaf | B11: Yuz qismi (eshiklar, tsokol) | C11: Laminat
A12: Shkaf | B12: Yon qismi (yon devorlar) | C12: Laminat | E12: =IF(shkaf_kra=1,"Bo'yaladigan yuza: "&ROUND(SUMIFS(Detallar!$Q$5:$Q$300,Detallar!$B$5:$B$300,"Shkaf",Detallar!$E$5:$E$300,"Yuz")*shkaf_kyuz+SUMIFS(Detallar!$Q$5:$Q$300,Detallar!$B$5:$B$300,"Shkaf",Detallar!$E$5:$E$300,"Yon")*shkaf_kyon,2)&" m²","")
A13: Krovat | B13: Krovat soni | C13: 1 | D13: dona
A14: Krovat | B14: Uzunligi (buyi) | C14: 220 | D14: sm
A15: Krovat | B15: Eni | C15: 170 | D15: sm
A16: Krovat | B16: Oyoq tomoni balandligi | C16: 45 | D16: sm
A17: Krovat | B17: Bosh tomoni (spinka) balandligi | C17: 150 | D17: sm
A18: Krovat | B18: Bosh spinkada figura | C18: Ha | E18: =IF(krovat_fig=1,"Figura: "&figura_W/10&"×"&figura_H/10&" sm (Sozlamalarda)","") -> Figura: 160×60 sm (Sozlamalarda)
A19: Krovat | B19: Kapot turi (matras tagi) | C19: Oddiy | E19: =IF(krovat_nasos=1,"Nasosli: DSP qirralari 2mm kromka + ko'tarish mexanizmi","Oddiy kapot (kromkasiz)") -> Oddiy kapot (kromkasiz)
A20: Krovat | B20: Matras | C20: 180x200 | E20: =IF(AND(p_matras<>"Yo'q",IFERROR(VALUE(LEFT(p_matras,3))*10,0)>krovat_ichW),"Diqqat: matras krovatga sig'maydi! Krovat ichi: ","Krovat ichi: ")&ROUND(krovat_ichW/10,1)&"×"&ROUND(krovat_ichL/10,1)&" sm" -> Diqqat: matras krovatga sig'maydi! Krovat ichi: 166,8×216,8 sm
A21: Trimo | B21: Trimo soni | C21: 1 | D21: dona
A22: Trimo | B22: Uzunligi | C22: 160 | D22: sm
A23: Trimo | B23: Chuqurligi (eni) | C23: 45 | D23: sm
A24: Trimo | B24: Balandligi | C24: 83 | D24: sm
A25: Trimo | B25: Yuz qismi (eshik, yashik fasadlari, tsokol) | C25: Laminat
A26: Trimo | B26: Yon qismi (yon devorlar, ustki qopqoq) | C26: Laminat | E26: =IF(trimo_kra=1,"Bo'yaladigan yuza: "&ROUND(SUMIFS(Detallar!$Q$5:$Q$300,Detallar!$B$5:$B$300,"Trimo",Detallar!$E$5:$E$300,"Yuz")*trimo_kyuz+SUMIFS(Detallar!$Q$5:$Q$300,Detallar!$B$5:$B$300,"Trimo",Detallar!$E$5:$E$300,"Yon")*trimo_kyon,2)&" m²","")
A27: Tumbochka | B27: Tumbochka soni | C27: 1 | D27: dona | E27: ="O'lcham: "&tumba_W/10&"×"&tumba_D/10&"×"&tumba_H/10&" sm" -> O'lcham: 50×40×60 sm
A28: Tumbochka | B28: Yuz qismi (yashik fasadlari, tsokol) | C28: Laminat
A29: Tumbochka | B29: Yon qismi (yon devorlar, ustki qopqoq) | C29: Laminat | E29: =IF(tumba_kra=1,"Bo'yaladigan yuza: "&ROUND(SUMIFS(Detallar!$Q$5:$Q$300,Detallar!$B$5:$B$300,"Tumbochka",Detallar!$E$5:$E$300,"Yuz")*tumba_kyuz+SUMIFS(Detallar!$Q$5:$Q$300,Detallar!$B$5:$B$300,"Tumbochka",Detallar!$E$5:$E$300,"Yon")*tumba_kyon,2)&" m²","")
A30: Chester | B30: Chester soni | C30: 1 | D30: dona | E30: ="O'lcham: "&chest_W/10&"×"&chest_D/10&"×"&chest_H/10&" sm" -> O'lcham: 80×50×100 sm
A31: Chester | B31: Yuz qismi (yashik fasadlari, tsokol) | C31: Laminat
A32: Chester | B32: Yon qismi (yon devorlar, ustki qopqoq) | C32: Laminat | E32: =IF(chest_kra=1,"Bo'yaladigan yuza: "&ROUND(SUMIFS(Detallar!$Q$5:$Q$300,Detallar!$B$5:$B$300,"Chester",Detallar!$E$5:$E$300,"Yuz")*chest_kyuz+SUMIFS(Detallar!$Q$5:$Q$300,Detallar!$B$5:$B$300,"Chester",Detallar!$E$5:$E$300,"Yon")*chest_kyon,2)&" m²","")
A33: Pufik | B33: Pufik soni | C33: 1 | D33: dona | E33: ="O'lcham: "&pufik_W/10&"×"&pufik_W/10&"×"&pufik_H/10&" sm" -> O'lcham: 40×40×45 sm
A34: Stoyka oyna | B34: Alohida stoyka oyna soni | C34: 1 | D34: dona | E34: ="Oyna: "&oyna_H/10&"×"&oyna_W/10&" sm" -> Oyna: 160×50 sm
A35: Usta | B35: Usta (Ustalar ro'yxatidan tanlang) | E35: =IF(p_usta="","Diqqat: usta tanlanmagan — usta haqi 0","Kelishuv: "&TEXT(usta_foiz,"0.0%")&" (xom ashyo summasiga)") -> Diqqat: usta tanlanmagan — usta haqi 0
A37: NARX HISOBI | D37: Joriy kurs (1 $): | E37: =kurs_joriy -> 11963
A38: Mahsulot | B38: Tavsif | C38: Soni | D38: Xom ashyo (so'm) | E38: Usta haqi (so'm) | F38: Tan narx (so'm) | G38: Sotuv narxi, naqd (so'm)
A39: Shkaf | B39: =Tannarx!B38 -> 240×60×220 sm, 6 eshik, 2 oyna, laminat | C39: =Tannarx!B5 -> 1 | D39: =Tannarx!B7 -> 3059239 | E39: =Tannarx!B9 -> 0 | F39: =Tannarx!B10 -> 3059239 | G39: =Tannarx!B13 -> 3060000
A40: Krovat | B40: =Tannarx!B39 -> 170×220 sm, spinka 150 sm, figurali, oddiy kapot | C40: =Tannarx!C5 -> 1 | D40: =Tannarx!C7 -> 1182540.8 | E40: =Tannarx!C9 -> 0 | F40: =Tannarx!C10 -> 1182540.8 | G40: =Tannarx!C13 -> 1183000
A41: Matras | B41: =Tannarx!B40 -> 180x200 sm | C41: =Tannarx!D5 -> 1 | D41: =Tannarx!D7 -> 1200000 | E41: =Tannarx!D9 -> 0 | F41: =Tannarx!D10 -> 1200000 | G41: =Tannarx!D13 -> 1200000
A42: Tumbochka | B42: =Tannarx!B41 -> 50×40×60 sm, 2 yashik, laminat | C42: =Tannarx!E5 -> 1 | D42: =Tannarx!E7 -> 578169.11 | E42: =Tannarx!E9 -> 0 | F42: =Tannarx!E10 -> 578169.11 | G42: =Tannarx!E13 -> 579000
...

Sheet Oshxona
A1: Oshxona mebeli — pogon metr bo'yicha hisoblash
A2: Sariq kataklarni to'ldiring: xomashyo, balandlik, uzunlik (metrda). Kerak bo'lsa 1 m narxini qo'lda yozing. Buyurtmaga qo'shish uchun "Buyurtma" varag'ida Oshxona mebeli = Ha qiling.
A4: № | B4: Xomashyo | C4: Balandligi (m) | D4: Uzunligi (m) | E4: 1 m narxi — jadvaldan ($) | F4: 1 m narxi — qo'lda ($) | G4: Hisobdagi 1 m narxi ($) | H4: Jami ($) | I4: Tan narx (so'm) | J4: Sotuv narxi, 1 m (so'm) | K4: Sotuv narxi, jami (so'm) | L4: Izoh
A5: 1 | B5: Akril | C5: 2.2 | D5: 3 | E5: =IF(OR(B5="",C5=""),"",IF(COUNTIFS(osh_t_mat,B5,osh_t_bal,C5)=0,"narx yo'q",SUMIFS(osh_t_narx,osh_t_mat,B5,osh_t_bal,C5))) -> 252 | G5: =IF(F5<>"",F5,IF(OR(E5="",E5="narx yo'q"),"",E5)) -> 252 | H5: =IF(OR(G5="",D5=""),"",D5*G5) -> 756 | I5: =IF(H5="","",H5*kurs_joriy) -> 9044028 | J5: =IF(G5="","",ROUNDUP(G5*kurs_joriy*(1+IF(LEFT(oshxona_narx_turi,3)="Tan",ustama_oshxona,0))/yaxlit,0)*yaxlit) -> 3015000 | K5: =IF(OR(J5="",D5=""),"",J5*D5) -> 9045000 | L5: namuna — o'chirib, o'zingiznikini yozing
A6: 2 | E6: =IF(OR(B6="",C6=""),"",IF(COUNTIFS(osh_t_mat,B6,osh_t_bal,C6)=0,"narx yo'q",SUMIFS(osh_t_narx,osh_t_mat,B6,osh_t_bal,C6))) | G6: =IF(F6<>"",F6,IF(OR(E6="",E6="narx yo'q"),"",E6)) | H6: =IF(OR(G6="",D6=""),"",D6*G6) | I6: =IF(H6="","",H6*kurs_joriy) | J6: =IF(G6="","",ROUNDUP(G6*kurs_joriy*(1+IF(LEFT(oshxona_narx_turi,3)="Tan",ustama_oshxona,0))/yaxlit,0)*yaxlit) | K6: =IF(OR(J6="",D6=""),"",J6*D6)
A7: 3 | E7: =IF(OR(B7="",C7=""),"",IF(COUNTIFS(osh_t_mat,B7,osh_t_bal,C7)=0,"narx yo'q",SUMIFS(osh_t_narx,osh_t_mat,B7,osh_t_bal,C7))) | G7: =IF(F7<>"",F7,IF(OR(E7="",E7="narx yo'q"),"",E7)) | H7: =IF(OR(G7="",D7=""),"",D7*G7) | I7: =IF(H7="","",H7*kurs_joriy) | J7: =IF(G7="","",ROUNDUP(G7*kurs_joriy*(1+IF(LEFT(oshxona_narx_turi,3)="Tan",ustama_oshxona,0))/yaxlit,0)*yaxlit) | K7: =IF(OR(J7="",D7=""),"",J7*D7)
A8: 4 | E8: =IF(OR(B8="",C8=""),"",IF(COUNTIFS(osh_t_mat,B8,osh_t_bal,C8)=0,"narx yo'q",SUMIFS(osh_t_narx,osh_t_mat,B8,osh_t_bal,C8))) | G8: =IF(F8<>"",F8,IF(OR(E8="",E8="narx yo'q"),"",E8)) | H8: =IF(OR(G8="",D8=""),"",D8*G8) | I8: =IF(H8="","",H8*kurs_joriy) | J8: =IF(G8="","",ROUNDUP(G8*kurs_joriy*(1+IF(LEFT(oshxona_narx_turi,3)="Tan",ustama_oshxona,0))/yaxlit,0)*yaxlit) | K8: =IF(OR(J8="",D8=""),"",J8*D8)
A9: 5 | E9: =IF(OR(B9="",C9=""),"",IF(COUNTIFS(osh_t_mat,B9,osh_t_bal,C9)=0,"narx yo'q",SUMIFS(osh_t_narx,osh_t_mat,B9,osh_t_bal,C9))) | G9: =IF(F9<>"",F9,IF(OR(E9="",E9="narx yo'q"),"",E9)) | H9: =IF(OR(G9="",D9=""),"",D9*G9) | I9: =IF(H9="","",H9*kurs_joriy) | J9: =IF(G9="","",ROUNDUP(G9*kurs_joriy*(1+IF(LEFT(oshxona_narx_turi,3)="Tan",ustama_oshxona,0))/yaxlit,0)*yaxlit) | K9: =IF(OR(J9="",D9=""),"",J9*D9)
A10: 6 | E10: =IF(OR(B10="",C10=""),"",IF(COUNTIFS(osh_t_mat,B10,osh_t_bal,C10)=0,"narx yo'q",SUMIFS(osh_t_narx,osh_t_mat,B10,osh_t_bal,C10))) | G10: =IF(F10<>"",F10,IF(OR(E10="",E10="narx yo'q"),"",E10)) | H10: =IF(OR(G10="",D10=""),"",D10*G10) | I10: =IF(H10="","",H10*kurs_joriy) | J10: =IF(G10="","",ROUNDUP(G10*kurs_joriy*(1+IF(LEFT(oshxona_narx_turi,3)="Tan",ustama_oshxona,0))/yaxlit,0)*yaxlit) | K10: =IF(OR(J10="",D10=""),"",J10*D10)
B11: JAMI | D11: =SUM(D5:D10) -> 3 | H11: =SUM(H5:H10) -> 756 | I11: =SUM(I5:I10) -> 9044028 | K11: =SUM(K5:K10) -> 9045000
A13: • Balandlik va uzunlikni xohlagan qiymatda yozish mumkin (ro'yxatdagidan boshqa ham). Jami ($) = Uzunligi × Hisobdagi 1 m narxi.
A14: • 1 m narxi: "qo'lda" ustuniga narx yozilsa, shu ishlatiladi. Bo'sh qolsa — "Oshxona narxlari" jadvalidan xomashyo va balandlik bo'yicha olinadi.
A15: • Jadvalda yo'q balandlik yozilsa ("narx yo'q" chiqadi) — narxni qo'lda yozing yoki "Oshxona narxlari" jadvaliga yangi qator qo'shing.
A16: • Dollar kursi — Sozlamalardagi joriy kurs. Baraka ustamasi va 1 m narxi turi — Sozlamalar, 1- va 7-bo'lim.
A18: =IF(COUNTIF(E5:E10,"narx yo'q")-COUNTIFS(E5:E10,"narx yo'q",F5:F10,"<>")>0,"Oshxona: "&(COUNTIF(E5:E10,"narx yo'q")-COUNTIFS(E5:E10,"narx yo'q",F5:F10,"<>"))&" qatorda narx yo'q — qo'lda yozing","")
A19: =IF(AND(LEFT(oshxona_narx_turi,3)="Tan",ustama_oshxona=0),"Oshxona: Baraka ustamasi 0% (Sozlamalar)","") -> Oshxona: Baraka ustamasi 0% (Sozlamalar)

Sheet Korpus mebel
A1: Korpus mebel — shkaf, prixojka, garderob (mijoz o'lchami bo'yicha)
A2: Har bir buyum uchun bitta ustun. O'lchamlarni sm da yozing. Bo'limlar va eshiklar sonini bo'sh qoldirsangiz, avtomatik hisoblanadi. Ishlatilmaydigan ustunda soni = 0 yoki bo'sh. Buyurtmaga qo'shish uchun "Buyurtma" varag'ida Korpus mebel = Ha qiling.
A4: Usta (Ustalar ro'yxatidan tanlang) | D4: =IF(p_k_usta="","Diqqat: usta tanlanmagan — usta haqi 0","Kelishuv: "&TEXT(usta_foiz_k,"0.0%")) -> Diqqat: usta tanlanmagan — usta haqi 0
A6: Ko'rsatkich | B6: Birlik | C6: Buyum 1 | D6: Buyum 2 | E6: Buyum 3 | F6: Buyum 4 | G6: Buyum 5 | H6: Buyum 6 | I6: Jami
A7: Turi | C7: Shkaf | D7: Prixojka | E7: Garderob
A8: Izoh (joyi, mijoz istagi) | C8: Namuna: yotoqxona | D8: Namuna: yo'lak | E8: Namuna: kiyim xonasi
A9: Soni | B9: dona | C9: 1 | D9: 1 | E9: 1 | F9: 0 | G9: 0 | H9: 0
A10: Uzunligi (eni) | B10: sm | C10: 200 | D10: 120 | E10: 300
A11: Balandligi | B11: sm | C11: 240 | D11: 220 | E11: 250
A12: Chuqurligi | B12: sm | C12: 60 | D12: 40 | E12: 50
A13: Bo'limlar soni (bo'sh = avtomatik) | B13: dona | E13: 4
A14: Eshik turi | C14: Kupe | D14: Oddiy | E14: Eshiksiz
A15: Eshiklar soni (bo'sh = avtomatik) | B15: dona | D15: 2
A16: Shundan oynali eshiklar | B16: dona | C16: 1 | D16: 1 | E16: 0
A17: Polkalar soni (jami) | B17: dona | C17: 6 | D17: 4 | E17: 10
A18: Yashiklar soni | B18: dona | C18: 2 | D18: 0 | E18: 2
A19: Kiyim ilgich (shtanga) bo'limlari | B19: dona | C19: 1 | D19: 0 | E19: 2
A20: Ilgaklar (kiyim ilmog'i) | B20: dona | C20: 0 | D20: 6 | E20: 0
A21: Orqa devor (DVP) | C21: Ha | D21: Ha | E21: Yo'q
A22: Yuz qismi (eshik, yashik, tsokol) | C22: Laminat | D22: Laminat | E22: Laminat
A23: Yon qismi (yon devorlar) | C23: Laminat | D23: Laminat | E23: Laminat
A25: NATIJA
A26: Bo'limlar (hisobda) | B26: dona | C26: =IF('Korpus hisob'!C11=0,"",'Korpus hisob'!C14) -> 3 | D26: =IF('Korpus hisob'!D11=0,"",'Korpus hisob'!D14) -> 2 | E26: =IF('Korpus hisob'!E11=0,"",'Korpus hisob'!E14) -> 4 | F26: =IF('Korpus hisob'!F11=0,"",'Korpus hisob'!F14) | G26: =IF('Korpus hisob'!G11=0,"",'Korpus hisob'!G14) | H26: =IF('Korpus hisob'!H11=0,"",'Korpus hisob'!H14)
A27: Eshiklar (hisobda) | B27: dona | C27: =IF('Korpus hisob'!C11=0,"",'Korpus hisob'!C15) -> 2 | D27: =IF('Korpus hisob'!D11=0,"",'Korpus hisob'!D15) -> 2 | E27: =IF('Korpus hisob'!E11=0,"",'Korpus hisob'!E15) -> 0 | F27: =IF('Korpus hisob'!F11=0,"",'Korpus hisob'!F15) | G27: =IF('Korpus hisob'!G11=0,"",'Korpus hisob'!G15) | H27: =IF('Korpus hisob'!H11=0,"",'Korpus hisob'!H15)
A28: Eshik o'lchami (eni × balandligi) | B28: sm | C28: =IF('Korpus hisob'!C11=0,"",IF('Korpus hisob'!C15=0,"—",ROUND('Korpus hisob'!C30/10,1)&" × "&ROUND('Korpus hisob'!C31/10,1))) -> 101,5 × 236 | D28: =IF('Korpus hisob'!D11=0,"",IF('Korpus hisob'!D15=0,"—",ROUND('Korpus hisob'!D30/10,1)&" × "&ROUND('Korpus hisob'!D31/10,1))) -> 59,7 × 211,7 | E28: =IF('Korpus hisob'!E11=0,"",IF('Korpus hisob'!E15=0,"—",ROUND('Korpus hisob'!E30/10,1)&" × "&ROUND('Korpus hisob'!E31/10,1))) -> — | F28: =IF('Korpus hisob'!F11=0,"",IF('Korpus hisob'!F15=0,"—",ROUND('Korpus hisob'!F30/10,1)&" × "&ROUND('Korpus hisob'!F31/10,1))) | G28: =IF('Korpus hisob'!G11=0,"",IF('Korpus hisob'!G15=0,"—",ROUND('Korpus hisob'!G30/10,1)&" × "&ROUND('Korpus hisob'!G31/10,1))) | H28: =IF('Korpus hisob'!H11=0,"",IF('Korpus hisob'!H15=0,"—",ROUND('Korpus hisob'!H30/10,1)&" × "&ROUND('Korpus hisob'!H31/10,1)))
A29: Plita (LDSP + MDF), 1 dona | B29: m² | C29: =IF('Korpus hisob'!C11=0,"",'Korpus hisob'!C93) -> 11.940973 | D29: =IF('Korpus hisob'!D11=0,"",'Korpus hisob'!D93) -> 6.845298 | E29: =IF('Korpus hisob'!E11=0,"",'Korpus hisob'!E93) -> 13.74584 | F29: =IF('Korpus hisob'!F11=0,"",'Korpus hisob'!F93) | G29: =IF('Korpus hisob'!G11=0,"",'Korpus hisob'!G93) | H29: =IF('Korpus hisob'!H11=0,"",'Korpus hisob'!H93)
A30: Bo'yaladigan maydon, 1 dona | B30: m² | C30: =IF('Korpus hisob'!C11=0,"",'Korpus hisob'!C49) -> 0 | D30: =IF('Korpus hisob'!D11=0,"",'Korpus hisob'!D49) -> 0 | E30: =IF('Korpus hisob'!E11=0,"",'Korpus hisob'!E49) -> 0 | F30: =IF('Korpus hisob'!F11=0,"",'Korpus hisob'!F49) | G30: =IF('Korpus hisob'!G11=0,"",'Korpus hisob'!G49) | H30: =IF('Korpus hisob'!H11=0,"",'Korpus hisob'!H49)
A31: Xom ashyo | B31: so'm | C31: =IF('Korpus hisob'!C11=0,"",'Korpus hisob'!C87) -> 2178652.3 | D31: =IF('Korpus hisob'!D11=0,"",'Korpus hisob'!D87) -> 1411005.4 | E31: =IF('Korpus hisob'!E11=0,"",'Korpus hisob'!E87) -> 1874358 | F31: =IF('Korpus hisob'!F11=0,"",'Korpus hisob'!F87) | G31: =IF('Korpus hisob'!G11=0,"",'Korpus hisob'!G87) | H31: =IF('Korpus hisob'!H11=0,"",'Korpus hisob'!H87) | I31: ='Korpus hisob'!I87 -> 5464015.8
A32: Usta haqi | B32: so'm | C32: =IF('Korpus hisob'!C11=0,"",'Korpus hisob'!C88) -> 0 | D32: =IF('Korpus hisob'!D11=0,"",'Korpus hisob'!D88) -> 0 | E32: =IF('Korpus hisob'!E11=0,"",'Korpus hisob'!E88) -> 0 | F32: =IF('Korpus hisob'!F11=0,"",'Korpus hisob'!F88) | G32: =IF('Korpus hisob'!G11=0,"",'Korpus hisob'!G88) | H32: =IF('Korpus hisob'!H11=0,"",'Korpus hisob'!H88) | I32: ='Korpus hisob'!I88 -> 0
A33: Tan narx | B33: so'm | C33: =IF('Korpus hisob'!C11=0,"",'Korpus hisob'!C89) -> 2178652.3 | D33: =IF('Korpus hisob'!D11=0,"",'Korpus hisob'!D89) -> 1411005.4 | E33: =IF('Korpus hisob'!E11=0,"",'Korpus hisob'!E89) -> 1874358 | F33: =IF('Korpus hisob'!F11=0,"",'Korpus hisob'!F89) | G33: =IF('Korpus hisob'!G11=0,"",'Korpus hisob'!G89) | H33: =IF('Korpus hisob'!H11=0,"",'Korpus hisob'!H89) | I33: ='Korpus hisob'!I89 -> 5464015.8
A34: Sotuv narxi — 1 dona (naqd) | B34: so'm | C34: =IF('Korpus hisob'!C11=0,"",'Korpus hisob'!C90) -> 2179000 | D34: =IF('Korpus hisob'!D11=0,"",'Korpus hisob'!D90) -> 1412000 | E34: =IF('Korpus hisob'!E11=0,"",'Korpus hisob'!E90) -> 1875000 | F34: =IF('Korpus hisob'!F11=0,"",'Korpus hisob'!F90) | G34: =IF('Korpus hisob'!G11=0,"",'Korpus hisob'!G90) | H34: =IF('Korpus hisob'!H11=0,"",'Korpus hisob'!H90)
A35: SOTUV NARXI (naqd) | B35: so'm | C35: =IF('Korpus hisob'!C11=0,"",'Korpus hisob'!C91) -> 2179000 | D35: =IF('Korpus hisob'!D11=0,"",'Korpus hisob'!D91) -> 1412000 | E35: =IF('Korpus hisob'!E11=0,"",'Korpus hisob'!E91) -> 1875000 | F35: =IF('Korpus hisob'!F11=0,"",'Korpus hisob'!F91) | G35: =IF('Korpus hisob'!G11=0,"",'Korpus hisob'!G91) | H35: =IF('Korpus hisob'!H11=0,"",'Korpus hisob'!H91) | I35: ='Korpus hisob'!I91 -> 5466000
A36: Narxi yo'q xom ashyo | B36: ta | C36: =IF('Korpus hisob'!C11=0,"",'Korpus hisob'!C92) -> 3 | D36: =IF('Korpus hisob'!D11=0,"",'Korpus hisob'!D92) -> 1 | E36: =IF('Korpus hisob'!E11=0,"",'Korpus hisob'!E92) -> 1 | F36: =IF('Korpus hisob'!F11=0,"",'Korpus hisob'!F92) | G36: =IF('Korpus hisob'!G11=0,"",'Korpus hisob'!G92) | H36: =IF('Korpus hisob'!H11=0,"",'Korpus hisob'!H92) | I36: ='Korpus hisob'!I92 -> 5
A38: Tavsif (mijoz varag'ida) | C38: =IF('Korpus hisob'!C11=0,"",'Korpus mebel'!C10&"×"&'Korpus mebel'!C12&"×"&'Korpus mebel'!C11&" sm, "&IF('Korpus hisob'!C15=0,"eshiksiz",'Korpus hisob'!C15&" ta "&IF('Korpus hisob'!C13=1,"kupe","oddiy")&" eshik")&IF('Korpus hisob'!C16>0,", "&'Korpus hisob'!C16&" oyna","")&", "&IF(AND('Korpus mebel'!C22="Krasheniy",'Korpus mebel'!C23="Krasheniy"),"to'liq krasheniy",IF('Korpus mebel'!C22="Krasheniy","yuzi krasheniy",IF('Korpus mebel'!C23="Krasheniy","yoni krasheniy","laminat")))&IF('Korpus mebel'!C8="",""," — "&'Korpus mebel'!C8)) -> 200×60×240 sm, 2 ta kupe eshik, 1 oyna, laminat — Namuna: yotoqxona | D38: =IF('Korpus hisob'!D11=0,"",'Korpus mebel'!D10&"×"&'Korpus mebel'!D12&"×"&'Korpus mebel'!D11&" sm, "&IF('Korpus hisob'!D15=0,"eshiksiz",'Korpus hisob'!D15&" ta "&IF('Korpus hisob'!D13=1,"kupe","oddiy")&" eshik")&IF('Korpus hisob'!D16>0,", "&'Korpus hisob'!D16&" oyna","")&", "&IF(AND('Korpus mebel'!D22="Krasheniy",'Korpus mebel'!D23="Krasheniy"),"to'liq krasheniy",IF('Korpus mebel'!D22="Krasheniy","yuzi krasheniy",IF('Korpus mebel'!D23="Krasheniy","yoni krasheniy","laminat")))&IF('Korpus mebel'!D8="",""," — "&'Korpus mebel'!D8)) -> 120×40×220 sm, 2 ta oddiy eshik, 1 oyna, laminat — Namuna: yo'lak | E38: =IF('Korpus hisob'!E11=0,"",'Korpus mebel'!E10&"×"&'Korpus mebel'!E12&"×"&'Korpus mebel'!E11&" sm, "&IF('Korpus hisob'!E15=0,"eshiksiz",'Korpus hisob'!E15&" ta "&IF('Korpus hisob'!E13=1,"kupe","oddiy")&" eshik")&IF('Korpus hisob'!E16>0,", "&'Korpus hisob'!E16&" oyna","")&", "&IF(AND('Korpus mebel'!E22="Krasheniy",'Korpus mebel'!E23="Krasheniy"),"to'liq krasheniy",IF('Korpus mebel'!E22="Krasheniy","yuzi krasheniy",IF('Korpus mebel'!E23="Krasheniy","yoni krasheniy","laminat")))&IF('Korpus mebel'!E8="",""," — "&'Korpus mebel'!E8)) -> 300×50×250 sm, eshiksiz, laminat — Namuna: kiyim xonasi | F38: =IF('Korpus hisob'!F11=0,"",'Korpus mebel'!F10&"×"&'Korpus mebel'!F12&"×"&'Korpus mebel'!F11&" sm, "&IF('Korpus hisob'!F15=0,"eshiksiz",'Korpus hisob'!F15&" ta "&IF('Korpus hisob'!F13=1,"kupe","oddiy")&" eshik")&IF('Korpus hisob'!F16>0,", "&'Korpus hisob'!F16&" oyna","")&", "&IF(AND('Korpus mebel'!F22="Krasheniy",'Korpus mebel'!F23="Krasheniy"),"to'liq krasheniy",IF('Korpus mebel'!F22="Krasheniy","yuzi krasheniy",IF('Korpus mebel'!F23="Krasheniy","yoni krasheniy","laminat")))&IF('Korpus mebel'!F8="",""," — "&'Korpus mebel'!F8)) | G38: =IF('Korpus hisob'!G11=0,"",'Korpus mebel'!G10&"×"&'Korpus mebel'!G12&"×"&'Korpus mebel'!G11&" sm, "&IF('Korpus hisob'!G15=0,"eshiksiz",'Korpus hisob'!G15&" ta "&IF('Korpus hisob'!G13=1,"kupe","oddiy")&" eshik")&IF('Korpus hisob'!G16>0,", "&'Korpus hisob'!G16&" oyna","")&", "&IF(AND('Korpus mebel'!G22="Krasheniy",'Korpus mebel'!G23="Krasheniy"),"to'liq krasheniy",IF('Korpus mebel'!G22="Krasheniy","yuzi krasheniy",IF('Korpus mebel'!G23="Krasheniy","yoni krasheniy","laminat")))&IF('Korpus mebel'!G8="",""," — "&'Korpus mebel'!G8)) | H38: =IF('Korpus hisob'!H11=0,"",'Korpus mebel'!H10&"×"&'Korpus mebel'!H12&"×"&'Korpus mebel'!H11&" sm, "&IF('Korpus hisob'!H15=0,"eshiksiz",'Korpus hisob'!H15&" ta "&IF('Korpus hisob'!H13=1,"kupe","oddiy")&" eshik")&IF('Korpus hisob'!H16>0,", "&'Korpus hisob'!H16&" oyna","")&", "&IF(AND('Korpus mebel'!H22="Krasheniy",'Korpus mebel'!H23="Krasheniy"),"to'liq krasheniy",IF('Korpus mebel'!H22="Krasheniy","yuzi krasheniy",IF('Korpus mebel'!H23="Krasheniy","yoni krasheniy","laminat")))&IF('Korpus mebel'!H8="",""," — "&'Korpus mebel'!H8))
A40: =IF(kor_miss>0,"Korpus mebel: "&kor_miss&" ta kerakli xom ashyoning narxi yo'q (Laminat/Krasheniy xom ashyo varag'i)","") -> Korpus mebel: 5 ta kerakli xom ashyoning narxi yo'q (Laminat/Krasheniy xom ashyo varag'i)
A41: =IF(usta_foiz_k=0,"Korpus mebel: usta tanlanmagan yoki kelishuv foizi 0%","") -> Korpus mebel: usta tanlanmagan yoki kelishuv foizi 0%
A42: =IF(ustama_korpus=0,"Korpus mebel: Baraka ustamasi 0% (Sozlamalar)","") -> Korpus mebel: Baraka ustamasi 0% (Sozlamalar)

Sheet Mijoz uchun
A1: =kompaniya_nomi -> BARAKA MEBEL
A2: =IF(kompaniya_kontakt="","",kompaniya_kontakt)
A4: NARX TAKLIFI
B6: Mijoz: | C6: =IF(p_mijoz="","",p_mijoz) | E6: Telefon: | F6: =IF(p_tel="","",p_tel)
B7: Sotuvchi: | C7: =IF(p_sotuvchi="","",p_sotuvchi) | E7: Sana: | F7: =IF(p_sana="","",p_sana) -> 46314
B8: =IF(p_filial="","","Filial:") | C8: =IF(p_filial="","",p_filial)
A10: Buyurtma tarkibi
A11: № | B11: Mahsulot | C11: Tavsif | D11: Miqdori | E11: Birlik narxi | F11: Summa (so'm)
A12: =IF($H12="","",1) -> 1 | B12: =IF($H12="","",INDEX('Ro''yxat'!$B$4:$B$24,$H12)) -> Shkaf | C12: =IF($H12="","",INDEX('Ro''yxat'!$C$4:$C$24,$H12)) -> 240×60×220 sm, 6 eshik, 2 oyna, laminat | D12: =IF($H12="","",INDEX('Ro''yxat'!$D$4:$D$24,$H12)) -> 1 dona | E12: =IF($H12="","",INDEX('Ro''yxat'!$E$4:$E$24,$H12)) -> 3060000 | F12: =IF($H12="","",INDEX('Ro''yxat'!$F$4:$F$24,$H12)) -> 3060000 | H12: =IFERROR(MATCH(1,'Ro''yxat'!$H$4:$H$24,0),"") -> 1
A13: =IF($H13="","",2) -> 2 | B13: =IF($H13="","",INDEX('Ro''yxat'!$B$4:$B$24,$H13)) -> Krovat | C13: =IF($H13="","",INDEX('Ro''yxat'!$C$4:$C$24,$H13)) -> 170×220 sm, spinka 150 sm, figurali, oddiy kapot | D13: =IF($H13="","",INDEX('Ro''yxat'!$D$4:$D$24,$H13)) -> 1 dona | E13: =IF($H13="","",INDEX('Ro''yxat'!$E$4:$E$24,$H13)) -> 1183000 | F13: =IF($H13="","",INDEX('Ro''yxat'!$F$4:$F$24,$H13)) -> 1183000 | H13: =IFERROR(MATCH(2,'Ro''yxat'!$H$4:$H$24,0),"") -> 2
A14: =IF($H14="","",3) -> 3 | B14: =IF($H14="","",INDEX('Ro''yxat'!$B$4:$B$24,$H14)) -> Matras | C14: =IF($H14="","",INDEX('Ro''yxat'!$C$4:$C$24,$H14)) -> 180x200 sm | D14: =IF($H14="","",INDEX('Ro''yxat'!$D$4:$D$24,$H14)) -> 1 dona | E14: =IF($H14="","",INDEX('Ro''yxat'!$E$4:$E$24,$H14)) -> 1200000 | F14: =IF($H14="","",INDEX('Ro''yxat'!$F$4:$F$24,$H14)) -> 1200000 | H14: =IFERROR(MATCH(3,'Ro''yxat'!$H$4:$H$24,0),"") -> 3
A15: =IF($H15="","",4) -> 4 | B15: =IF($H15="","",INDEX('Ro''yxat'!$B$4:$B$24,$H15)) -> Tumbochka | C15: =IF($H15="","",INDEX('Ro''yxat'!$C$4:$C$24,$H15)) -> 50×40×60 sm, 2 yashik, laminat | D15: =IF($H15="","",INDEX('Ro''yxat'!$D$4:$D$24,$H15)) -> 1 dona | E15: =IF($H15="","",INDEX('Ro''yxat'!$E$4:$E$24,$H15)) -> 579000 | F15: =IF($H15="","",INDEX('Ro''yxat'!$F$4:$F$24,$H15)) -> 579000 | H15: =IFERROR(MATCH(4,'Ro''yxat'!$H$4:$H$24,0),"") -> 4
A16: =IF($H16="","",5) -> 5 | B16: =IF($H16="","",INDEX('Ro''yxat'!$B$4:$B$24,$H16)) -> Trimo | C16: =IF($H16="","",INDEX('Ro''yxat'!$C$4:$C$24,$H16)) -> 160×45×83 sm, laminat | D16: =IF($H16="","",INDEX('Ro''yxat'!$D$4:$D$24,$H16)) -> 1 dona | E16: =IF($H16="","",INDEX('Ro''yxat'!$E$4:$E$24,$H16)) -> 1383000 | F16: =IF($H16="","",INDEX('Ro''yxat'!$F$4:$F$24,$H16)) -> 1383000 | H16: =IFERROR(MATCH(5,'Ro''yxat'!$H$4:$H$24,0),"") -> 5
A17: =IF($H17="","",6) -> 6 | B17: =IF($H17="","",INDEX('Ro''yxat'!$B$4:$B$24,$H17)) -> Chester | C17: =IF($H17="","",INDEX('Ro''yxat'!$C$4:$C$24,$H17)) -> 80×50×100 sm, 4 yashik, laminat | D17: =IF($H17="","",INDEX('Ro''yxat'!$D$4:$D$24,$H17)) -> 1 dona | E17: =IF($H17="","",INDEX('Ro''yxat'!$E$4:$E$24,$H17)) -> 1302000 | F17: =IF($H17="","",INDEX('Ro''yxat'!$F$4:$F$24,$H17)) -> 1302000 | H17: =IFERROR(MATCH(6,'Ro''yxat'!$H$4:$H$24,0),"") -> 6
A18: =IF($H18="","",7) -> 7 | B18: =IF($H18="","",INDEX('Ro''yxat'!$B$4:$B$24,$H18)) -> Pufik | C18: =IF($H18="","",INDEX('Ro''yxat'!$C$4:$C$24,$H18)) -> 40×40×45 sm | D18: =IF($H18="","",INDEX('Ro''yxat'!$D$4:$D$24,$H18)) -> 1 dona | E18: =IF($H18="","",INDEX('Ro''yxat'!$E$4:$E$24,$H18)) -> 186000 | F18: =IF($H18="","",INDEX('Ro''yxat'!$F$4:$F$24,$H18)) -> 186000 | H18: =IFERROR(MATCH(7,'Ro''yxat'!$H$4:$H$24,0),"") -> 7
A19: =IF($H19="","",8) -> 8 | B19: =IF($H19="","",INDEX('Ro''yxat'!$B$4:$B$24,$H19)) -> Stoyka oyna | C19: =IF($H19="","",INDEX('Ro''yxat'!$C$4:$C$24,$H19)) -> 160×50 sm | D19: =IF($H19="","",INDEX('Ro''yxat'!$D$4:$D$24,$H19)) -> 1 dona | E19: =IF($H19="","",INDEX('Ro''yxat'!$E$4:$E$24,$H19)) -> 412000 | F19: =IF($H19="","",INDEX('Ro''yxat'!$F$4:$F$24,$H19)) -> 412000 | H19: =IFERROR(MATCH(8,'Ro''yxat'!$H$4:$H$24,0),"") -> 8
A20: =IF($H20="","",9) -> 9 | B20: =IF($H20="","",INDEX('Ro''yxat'!$B$4:$B$24,$H20)) -> Qadoqlash | C20: =IF($H20="","",INDEX('Ro''yxat'!$C$4:$C$24,$H20)) -> Butun buyurtma uchun | D20: =IF($H20="","",INDEX('Ro''yxat'!$D$4:$D$24,$H20)) -> 1 dona | E20: =IF($H20="","",INDEX('Ro''yxat'!$E$4:$E$24,$H20)) -> 355000 | F20: =IF($H20="","",INDEX('Ro''yxat'!$F$4:$F$24,$H20)) -> 355000 | H20: =IFERROR(MATCH(9,'Ro''yxat'!$H$4:$H$24,0),"") -> 9
A21: =IF($H21="","",10) | B21: =IF($H21="","",INDEX('Ro''yxat'!$B$4:$B$24,$H21)) | C21: =IF($H21="","",INDEX('Ro''yxat'!$C$4:$C$24,$H21)) | D21: =IF($H21="","",INDEX('Ro''yxat'!$D$4:$D$24,$H21)) | E21: =IF($H21="","",INDEX('Ro''yxat'!$E$4:$E$24,$H21)) | F21: =IF($H21="","",INDEX('Ro''yxat'!$F$4:$F$24,$H21)) | H21: =IFERROR(MATCH(10,'Ro''yxat'!$H$4:$H$24,0),"")
A22: =IF($H22="","",11) | B22: =IF($H22="","",INDEX('Ro''yxat'!$B$4:$B$24,$H22)) | C22: =IF($H22="","",INDEX('Ro''yxat'!$C$4:$C$24,$H22)) | D22: =IF($H22="","",INDEX('Ro''yxat'!$D$4:$D$24,$H22)) | E22: =IF($H22="","",INDEX('Ro''yxat'!$E$4:$E$24,$H22)) | F22: =IF($H22="","",INDEX('Ro''yxat'!$F$4:$F$24,$H22)) | H22: =IFERROR(MATCH(11,'Ro''yxat'!$H$4:$H$24,0),"")
A23: =IF($H23="","",12) | B23: =IF($H23="","",INDEX('Ro''yxat'!$B$4:$B$24,$H23)) | C23: =IF($H23="","",INDEX('Ro''yxat'!$C$4:$C$24,$H23)) | D23: =IF($H23="","",INDEX('Ro''yxat'!$D$4:$D$24,$H23)) | E23: =IF($H23="","",INDEX('Ro''yxat'!$E$4:$E$24,$H23)) | F23: =IF($H23="","",INDEX('Ro''yxat'!$F$4:$F$24,$H23)) | H23: =IFERROR(MATCH(12,'Ro''yxat'!$H$4:$H$24,0),"")
A24: =IF($H24="","",13) | B24: =IF($H24="","",INDEX('Ro''yxat'!$B$4:$B$24,$H24)) | C24: =IF($H24="","",INDEX('Ro''yxat'!$C$4:$C$24,$H24)) | D24: =IF($H24="","",INDEX('Ro''yxat'!$D$4:$D$24,$H24)) | E24: =IF($H24="","",INDEX('Ro''yxat'!$E$4:$E$24,$H24)) | F24: =IF($H24="","",INDEX('Ro''yxat'!$F$4:$F$24,$H24)) | H24: =IFERROR(MATCH(13,'Ro''yxat'!$H$4:$H$24,0),"")
A25: =IF($H25="","",14) | B25: =IF($H25="","",INDEX('Ro''yxat'!$B$4:$B$24,$H25)) | C25: =IF($H25="","",INDEX('Ro''yxat'!$C$4:$C$24,$H25)) | D25: =IF($H25="","",INDEX('Ro''yxat'!$D$4:$D$24,$H25)) | E25: =IF($H25="","",INDEX('Ro''yxat'!$E$4:$E$24,$H25)) | F25: =IF($H25="","",INDEX('Ro''yxat'!$F$4:$F$24,$H25)) | H25: =IFERROR(MATCH(14,'Ro''yxat'!$H$4:$H$24,0),"")
A26: =IF($H26="","",15) | B26: =IF($H26="","",INDEX('Ro''yxat'!$B$4:$B$24,$H26)) | C26: =IF($H26="","",INDEX('Ro''yxat'!$C$4:$C$24,$H26)) | D26: =IF($H26="","",INDEX('Ro''yxat'!$D$4:$D$24,$H26)) | E26: =IF($H26="","",INDEX('Ro''yxat'!$E$4:$E$24,$H26)) | F26: =IF($H26="","",INDEX('Ro''yxat'!$F$4:$F$24,$H26)) | H26: =IFERROR(MATCH(15,'Ro''yxat'!$H$4:$H$24,0),"")
A27: =IF($H27="","",16) | B27: =IF($H27="","",INDEX('Ro''yxat'!$B$4:$B$24,$H27)) | C27: =IF($H27="","",INDEX('Ro''yxat'!$C$4:$C$24,$H27)) | D27: =IF($H27="","",INDEX('Ro''yxat'!$D$4:$D$24,$H27)) | E27: =IF($H27="","",INDEX('Ro''yxat'!$E$4:$E$24,$H27)) | F27: =IF($H27="","",INDEX('Ro''yxat'!$F$4:$F$24,$H27)) | H27: =IFERROR(MATCH(16,'Ro''yxat'!$H$4:$H$24,0),"")
B28: =IF(chegirma_summa>0,"JAMI","JAMI (naqd narx)") -> JAMI (naqd narx) | F28: =jami_sotuv -> 9660000
B29: =IF(chegirma_summa>0,"Chegirma ("&TEXT(p_chegirma,"0%")&")","") | F29: =IF(chegirma_summa>0,-chegirma_summa,"")
B30: =IF(chegirma_summa>0,"NAQD NARX (chegirma bilan)","") | F30: =IF(chegirma_summa>0,naqd_chegirma_bilan,"")
A32: To'lov sharti
B33: To'lov turi: | C33: =IF(tanlangan_oy=0,"Naqd to'lov","Muddatli to'lov — "&tanlangan_oy&" oy") -> Naqd to'lov
B34: =IF(tanlangan_oy=0,"To'lov summasi:","Oldindan to'lov:") -> To'lov summasi: | C34: =IF(tanlangan_oy=0,naqd_narx,old_tolov) -> 9660000
B35: =IF(tanlangan_oy=0,"","Oylik to'lov:") | C35: =IF(tanlangan_oy=0,"",TEXT(tanlangan_oylik,"#,##0")&" so'm × "&tanlangan_oy&" oy")
B36: =IF(tanlangan_oy=0,"","Jami to'lov:") | C36: =IF(tanlangan_oy=0,"",tanlangan_jami)
A38: To'lov variantlari | C38: ="oldindan to'lov: "&TEXT(old_tolov,"#,##0")&" so'm" -> oldindan to'lov: ,0 so'm
B39: To'lov turi | C39: Oylik to'lov (so'm) | D39: Oy | E39: Oldindan to'lov | F39: Jami to'lov (so'm)
B40: =Tariflar!A38 -> Naqd | C40: — | E40: — | F40: =Tariflar!F38 -> 9660000
B41: =Tariflar!A39 -> 3 oy | C41: =Tariflar!E39 -> 3703000 | D41: ="× "&Tariflar!B39 -> × 3 | E41: =old_tolov -> 0 | F41: =Tariflar!F39 -> 11109000
B42: =Tariflar!A40 -> 6 oy | C42: =Tariflar!E40 -> 1997000 | D42: ="× "&Tariflar!B40 -> × 6 | E42: =old_tolov -> 0 | F42: =Tariflar!F40 -> 11982000
B43: =Tariflar!A41 -> 12 oy | C43: =Tariflar!E41 -> 1144000 | D43: ="× "&Tariflar!B41 -> × 12 | E43: =old_tolov -> 0 | F43: =Tariflar!F41 -> 13728000
B44: =Tariflar!A42 -> 18 oy | C44: =Tariflar!E42 -> 856000 | D44: ="× "&Tariflar!B42 -> × 18 | E44: =old_tolov -> 0 | F44: =Tariflar!F42 -> 15408000
A46: ="Narxlar "&IF(p_sana="","",TEXT(p_sana,"dd.mm.yyyy"))&" holatiga ko'ra hisoblangan. Yashil qator — tanlangan to'lov turi." -> Narxlar dd.mm.yyyy holatiga ko'ra hisoblangan. Yashil qator — tanlangan to'lov turi.
...

Sheet Ustalar
A1: Ustalar ro'yxati
A2: Har bir usta bilan kelishilgan foizni kiriting. Usta haqi = buyurtmaning xom ashyo summasi × kelishuv %. Panelda usta shu ro'yxatdan tanlanadi. Sariq kataklarni to'ldiring.
A3: Namuna (to'ldirish formati): Karimov Anvar | +998 90 123 45 67 | Korpus mebel | Qo'qon sh., Navoiy ko'chasi | 18% | 01.10.2026
A5: № | B5: Usta F.I.O. | C5: Telefon | D5: Ish turi (mutaxassisligi) | E5: Ustaxona / manzil | F5: Kelishuv, % (xom ashyo summasiga) | G5: Shartnoma sanasi | H5: Izoh
A6: 1
A7: 2
A8: 3
A9: 4
A10: 5
A11: 6
A12: 7
A13: 8
A14: 9
A15: 10
A16: 11
A17: 12
... A55: 50

Sheet Laminat xom ashyo
A1: Laminat xom ashyo — narxlar va sarf
A2: Barcha mahsulotlar LAMINAT variantida hisoblanadi (krovat kapoti — DSP). Shkaf, trimo, chester, tumbochkada panelda krasheniy tanlansa, buyurtma tannarxi o'sha mahsulot uchun Krasheniy varag'idan olinadi, bu yerdagi miqdor esa taqqoslash uchun qoladi. Sariq kataklar — 1 birlik narxi. Mahsulot ustunlari — sof sarf (otxodsiz).
C3: Joriy kurs (1 $): | D3: =kurs_joriy -> 11963
A4: № | B4: Guruh | C4: Xom ashyo | D4: Birlik | E4: Shkaf | F4: Krovat | G4: Matras | H4: Tumbochka | I4: Trimo | J4: Chester | K4: Pufik | L4: Stoyka oyna | M4: Qadoqlash | N4: Jami sof | O4: Otxod / zapas | P4: Jami kerak | Q4: Narx turi | R4: Narx (kiritilgan) | S4: Narx (so'm, joriy kurs) | T4: Summa (so'm) | U4: Summa ($) | V4: Izoh
A5: 1 | B5: Asosiy | C5: LDSP 16mm (laminat) | D5: list | E5: =SUMIFS(Detallar!$I$5:$I$300,Detallar!$B$5:$B$300,E$4,Detallar!$D$5:$D$300,"LDSP 16mm")/(ldsp_L*ldsp_W/1000000) -> 2.7726001 | F5: =SUMIFS(Detallar!$I$5:$I$300,Detallar!$B$5:$B$300,F$4,Detallar!$D$5:$D$300,"LDSP 16mm")/(ldsp_L*ldsp_W/1000000) -> 1.0742236 | G5: =SUMIFS(Detallar!$I$5:$I$300,Detallar!$B$5:$B$300,G$4,Detallar!$D$5:$D$300,"LDSP 16mm")/(ldsp_L*ldsp_W/1000000) -> 0 | H5: =SUMIFS(Detallar!$I$5:$I$300,Detallar!$B$5:$B$300,H$4,Detallar!$D$5:$D$300,"LDSP 16mm")/(ldsp_L*ldsp_W/1000000) -> 0.29118875 | I5: =SUMIFS(Detallar!$I$5:$I$300,Detallar!$B$5:$B$300,I$4,Detallar!$D$5:$D$300,"LDSP 16mm")/(ldsp_L*ldsp_W/1000000) -> 0.92537992 | J5: =SUMIFS(Detallar!$I$5:$I$300,Detallar!$B$5:$B$300,J$4,Detallar!$D$5:$D$300,"LDSP 16mm")/(ldsp_L*ldsp_W/1000000) -> 0.69172326 | K5: =SUMIFS(Detallar!$I$5:$I$300,Detallar!$B$5:$B$300,K$4,Detallar!$D$5:$D$300,"LDSP 16mm")/(ldsp_L*ldsp_W/1000000) -> 0.12035887 | L5: =SUMIFS(Detallar!$I$5:$I$300,Detallar!$B$5:$B$300,L$4,Detallar!$D$5:$D$300,"LDSP 16mm")/(ldsp_L*ldsp_W/1000000) -> 0.23809524 | M5: =SUMIFS(Detallar!$I$5:$I$300,Detallar!$B$5:$B$300,M$4,Detallar!$D$5:$D$300,"LDSP 16mm")/(ldsp_L*ldsp_W/1000000) -> 0 | N5: =SUM(E5:M5) -> 6.1135697 | O5: 0.15 | P5: =N5*(1+O5) -> 7.0306052 | Q5: So'm (kursga bog'liq) | R5: 400000 | S5: =IF(Q5="Dollar",R5*kurs_joriy,IF(Q5="So'm (kursga bog'liq)",R5*kurs_joriy/kurs_baza,R5)) -> 400000 | T5: =P5*S5 -> 2812242.1 | U5: =T5/kurs_joriy -> 235.07833 | V5: Narx 1 list uchun
A6: 2 | B6: Asosiy | C6: DSP 16mm — oddiy kapot | D6: list | E6: =SUMIFS(Detallar!$I$5:$I$300,Detallar!$B$5:$B$300,E$4,Detallar!$D$5:$D$300,"DSP 16mm (oddiy kapot)")/(dsp_L*dsp_W/1000000) -> 0 | F6: =SUMIFS(Detallar!$I$5:$I$300,Detallar!$B$5:$B$300,F$4,Detallar!$D$5:$D$300,"DSP 16mm (oddiy kapot)")/(dsp_L*dsp_W/1000000) -> 0.71685087 | G6: =SUMIFS(Detallar!$I$5:$I$300,Detallar!$B$5:$B$300,G$4,Detallar!$D$5:$D$300,"DSP 16mm (oddiy kapot)")/(dsp_L*dsp_W/1000000) -> 0 | H6: =SUMIFS(Detallar!$I$5:$I$300,Detallar!$B$5:$B$300,H$4,Detallar!$D$5:$D$300,"DSP 16mm (oddiy kapot)")/(dsp_L*dsp_W/1000000) -> 0 | I6: =SUMIFS(Detallar!$I$5:$I$300,Detallar!$B$5:$B$300,I$4,Detallar!$D$5:$D$300,"DSP 16mm (oddiy kapot)")/(dsp_L*dsp_W/1000000) -> 0 | J6: =SUMIFS(Detallar!$I$5:$I$300,Detallar!$B$5:$B$300,J$4,Detallar!$D$5:$D$300,"DSP 16mm (oddiy kapot)")/(dsp_L*dsp_W/1000000) -> 0 | K6: =SUMIFS(Detallar!$I$5:$I$300,Detallar!$B$5:$B$300,K$4,Detallar!$D$5:$D$300,"DSP 16mm (oddiy kapot)")/(dsp_L*dsp_W/1000000) -> 0 | L6: =SUMIFS(Detallar!$I$5:$I$300,Detallar!$B$5:$B$300,L$4,Detallar!$D$5:$D$300,"DSP 16mm (oddiy kapot)")/(dsp_L*dsp_W/1000000) -> 0 | M6: =SUMIFS(Detallar!$I$5:$I$300,Detallar!$B$5:$B$300,M$4,Detallar!$D$5:$D$300,"DSP 16mm (oddiy kapot)")/(dsp_L*dsp_W/1000000) -> 0 | N6: =SUM(E6:M6) -> 0.71685087 | O6: 0.15 | P6: =N6*(1+O6) -> 0.8243785 | Q6: So'm (kursga bog'liq) | S6: =IF(Q6="Dollar",R6*kurs_joriy,IF(Q6="So'm (kursga bog'liq)",R6*kurs_joriy/kurs_baza,R6)) -> 0 | T6: =P6*S6 -> 0 | U6: =T6/kurs_joriy -> 0 | V6: Krovat kapoti (matras tagi), oddiy; narx 1 list uchun
A7: 3 | B7: Asosiy | C7: DSP 16mm — nasosli kapot | D7: list | E7: =SUMIFS(Detallar!$I$5:$I$300,Detallar!$B$5:$B$300,E$4,Detallar!$D$5:$D$300,"DSP 16mm (nasosli kapot)")/(dsp_L*dsp_W/1000000) -> 0 | F7: =SUMIFS(Detallar!$I$5:$I$300,Detallar!$B$5:$B$300,F$4,Detallar!$D$5:$D$300,"DSP 16mm (nasosli kapot)")/(dsp_L*dsp_W/1000000) -> 0 | G7: =SUMIFS(Detallar!$I$5:$I$300,Detallar!$B$5:$B$300,G$4,Detallar!$D$5:$D$300,"DSP 16mm (nasosli kapot)")/(dsp_L*dsp_W/1000000) -> 0 | H7: =SUMIFS(Detallar!$I$5:$I$300,Detallar!$B$5:$B$300,H$4,Detallar!$D$5:$D$300,"DSP 16mm (nasosli kapot)")/(dsp_L*dsp_W/1000000) -> 0 | I7: =SUMIFS(Detallar!$I$5:$I$300,Detallar!$B$5:$B$300,I$4,Detallar!$D$5:$D$300,"DSP 16mm (nasosli kapot)")/(dsp_L*dsp_W/1000000) -> 0 | J7: =SUMIFS(Detallar!$I$5:$I$300,Detallar!$B$5:$B$300,J$4,Detallar!$D$5:$D$300,"DSP 16mm (nasosli kapot)")/(dsp_L*dsp_W/1000000) -> 0 | K7: =SUMIFS(Detallar!$I$5:$I$300,Detallar!$B$5:$B$300,K$4,Detallar!$D$5:$D$300,"DSP 16mm (nasosli kapot)")/(dsp_L*dsp_W/1000000) -> 0 | L7: =SUMIFS(Detallar!$I$5:$I$300,Detallar!$B$5:$B$300,L$4,Detallar!$D$5:$D$300,"DSP 16mm (nasosli kapot)")/(dsp_L*dsp_W/1000000) -> 0 | M7: =SUMIFS(Detallar!$I$5:$I$300,Detallar!$B$5:$B$300,M$4,Detallar!$D$5:$D$300,"DSP 16mm (nasosli kapot)")/(dsp_L*dsp_W/1000000) -> 0 | N7: =SUM(E7:M7) -> 0 | O7: 0.15 | P7: =N7*(1+O7) -> 0 | Q7: So'm (kursga bog'liq) | S7: =IF(Q7="Dollar",R7*kurs_joriy,IF(Q7="So'm (kursga bog'liq)",R7*kurs_joriy/kurs_baza,R7)) -> 0 | T7: =P7*S7 -> 0 | U7: =T7/kurs_joriy -> 0 | V7: Krovat kapoti, nasosli; narx 1 list uchun
A8: 4 | B8: Asosiy | C8: DVP 3mm (orqa devor, yashik tagi) | D8: list | E8: =SUMIFS(Detallar!$I$5:$I$300,Detallar!$B$5:$B$300,E$4,Detallar!$D$5:$D$300,"DVP 3mm")/(dvp_L*dvp_W/1000000) -> 1.1237647 | F8: =SUMIFS(Detallar!$I$5:$I$300,Detallar!$B$5:$B$300,F$4,Detallar!$D$5:$D$300,"DVP 3mm")/(dvp_L*dvp_W/1000000) -> 0 | G8: =SUMIFS(Detallar!$I$5:$I$300,Detallar!$B$5:$B$300,G$4,Detallar!$D$5:$D$300,"DVP 3mm")/(dvp_L*dvp_W/1000000) -> 0 | H8: =SUMIFS(Detallar!$I$5:$I$300,Detallar!$B$5:$B$300,H$4,Detallar!$D$5:$D$300,"DVP 3mm")/(dvp_L*dvp_W/1000000) -> 0.12795028 | I8: =SUMIFS(Detallar!$I$5:$I$300,Detallar!$B$5:$B$300,I$4,Detallar!$D$5:$D$300,"DVP 3mm")/(dvp_L*dvp_W/1000000) -> 0.40200579 | J8: =SUMIFS(Detallar!$I$5:$I$300,Detallar!$B$5:$B$300,J$4,Detallar!$D$5:$D$300,"DVP 3mm")/(dvp_L*dvp_W/1000000) -> 0.45337619 | K8: =SUMIFS(Detallar!$I$5:$I$300,Detallar!$B$5:$B$300,K$4,Detallar!$D$5:$D$300,"DVP 3mm")/(dvp_L*dvp_W/1000000) -> 0.034286939 | L8: =SUMIFS(Detallar!$I$5:$I$300,Detallar!$B$5:$B$300,L$4,Detallar!$D$5:$D$300,"DVP 3mm")/(dvp_L*dvp_W/1000000) -> 0 | M8: =SUMIFS(Detallar!$I$5:$I$300,Detallar!$B$5:$B$300,M$4,Detallar!$D$5:$D$300,"DVP 3mm")/(dvp_L*dvp_W/1000000) -> 0 | N8: =SUM(E8:M8) -> 2.1413839 | O8: 0.15 | P8: =N8*(1+O8) -> 2.4625915 | Q8: So'm (kursga bog'liq) | R8: 190000 | S8: =IF(Q8="Dollar",R8*kurs_joriy,IF(Q8="So'm (kursga bog'liq)",R8*kurs_joriy/kurs_baza,R8)) -> 190000 | T8: =P8*S8 -> 467892.38 | U8: =T8/kurs_joriy -> 39.111626 | V8: Narx 1 list uchun
A9: 5 | B9: Asosiy | C9: Oyna 4mm (ko'zgu) | D9: m² | E9: =SUMIFS(Detallar!$I$5:$I$300,Detallar!$B$5:$B$300,E$4,Detallar!$D$5:$D$300,"Oyna 4mm") -> 1.6 | F9: =SUMIFS(Detallar!$I$5:$I$300,Detallar!$B$5:$B$300,F$4,Detallar!$D$5:$D$300,"Oyna 4mm") -> 0 | G9: =SUMIFS(Detallar!$I$5:$I$300,Detallar!$B$5:$B$300,G$4,Detallar!$D$5:$D$300,"Oyna 4mm") -> 0 | H9: =SUMIFS(Detallar!$I$5:$I$300,Detallar!$B$5:$B$300,H$4,Detallar!$D$5:$D$300,"Oyna 4mm") -> 0 | I9: =SUMIFS(Detallar!$I$5:$I$300,Detallar!$B$5:$B$300,I$4,Detallar!$D$5:$D$300,"Oyna 4mm") -> 0 | J9: =SUMIFS(Detallar!$I$5:$I$300,Detallar!$B$5:$B$300,J$4,Detallar!$D$5:$D$300,"Oyna 4mm") -> 0 | K9: =SUMIFS(Detallar!$I$5:$I$300,Detallar!$B$5:$B$300,K$4,Detallar!$D$5:$D$300,"Oyna 4mm") -> 0 | L9: =SUMIFS(Detallar!$I$5:$I$300,Detallar!$B$5:$B$300,L$4,Detallar!$D$5:$D$300,"Oyna 4mm") -> 0.8 | M9: =SUMIFS(Detallar!$I$5:$I$300,Detallar!$B$5:$B$300,M$4,Detallar!$D$5:$D$300,"Oyna 4mm") -> 0 | N9: =SUM(E9:M9) -> 2.4 | O9: 0 | P9: =N9*(1+O9) -> 2.4 | Q9: So'm (kursga bog'liq) | R9: 140000 | S9: =IF(Q9="Dollar",R9*kurs_joriy,IF(Q9="So'm (kursga bog'liq)",R9*kurs_joriy/kurs_baza,R9)) -> 140000 | T9: =P9*S9 -> 336000 | U9: =T9/kurs_joriy -> 28.0866 | V9: Shkaf eshik oynalari + stoyka oyna
A10: 6 | B10: Asosiy | C10: Kromka PVX 2mm | D10: m | E10: =SUMIFS(Detallar!$N$5:$N$300,Detallar!$B$5:$B$300,E$4) -> 30.168 | F10: =SUMIFS(Detallar!$N$5:$N$300,Detallar!$B$5:$B$300,F$4) -> 21.636 | G10: =SUMIFS(Detallar!$N$5:$N$300,Detallar!$B$5:$B$300,G$4) -> 0 | H10: =SUMIFS(Detallar!$N$5:$N$300,Detallar!$B$5:$B$300,H$4) -> 4.284 | I10: =SUMIFS(Detallar!$N$5:$N$300,Detallar!$B$5:$B$300,I$4) -> 12.17 | J10: =SUMIFS(Detallar!$N$5:$N$300,Detallar!$B$5:$B$300,J$4) -> 9.96 | K10: =SUMIFS(Detallar!$N$5:$N$300,Detallar!$B$5:$B$300,K$4) -> 0 | L10: =SUMIFS(Detallar!$N$5:$N$300,Detallar!$B$5:$B$300,L$4) -> 7.6 | M10: =SUMIFS(Detallar!$N$5:$N$300,Detallar!$B$5:$B$300,M$4) -> 0 | N10: =SUM(E10:M10) -> 85.818 | O10: 0.1 | P10: =N10*(1+O10) -> 94.3998 | Q10: So'm (kursga bog'liq) | R10: 4000 | S10: =IF(Q10="Dollar",R10*kurs_joriy,IF(Q10="So'm (kursga bog'liq)",R10*kurs_joriy/kurs_baza,R10)) -> 4000 | T10: =P10*S10 -> 377599.2 | U10: =T10/kurs_joriy -> 31.563922 | V10: Narx kromkalash xizmati bilan; nasosli kapot qirralari ham shu yerda
A11: 7 | B11: Asosiy | C11: Kromka PVX 0.4mm | D11: m | E11: =SUMIFS(Detallar!$O$5:$O$300,Detallar!$B$5:$B$300,E$4) -> 22.28 | F11: =SUMIFS(Detallar!$O$5:$O$300,Detallar!$B$5:$B$300,F$4) -> 4.336 | G11: =SUMIFS(Detallar!$O$5:$O$300,Detallar!$B$5:$B$300,G$4) -> 0 | H11: =SUMIFS(Detallar!$O$5:$O$300,Detallar!$B$5:$B$300,H$4) -> 5.144 | I11: =SUMIFS(Detallar!$O$5:$O$300,Detallar!$B$5:$B$300,I$4) -> 12.344 | J11: =SUMIFS(Detallar!$O$5:$O$300,Detallar!$B$5:$B$300,J$4) -> 12.784 | K11: =SUMIFS(Detallar!$O$5:$O$300,Detallar!$B$5:$B$300,K$4) -> 0 | L11: =SUMIFS(Detallar!$O$5:$O$300,Detallar!$B$5:$B$300,L$4) -> 0 | M11: =SUMIFS(Detallar!$O$5:$O$300,Detallar!$B$5:$B$300,M$4) -> 0 | N11: =SUM(E11:M11) -> 56.888 | O11: 0.1 | P11: =N11*(1+O11) -> 62.5768 | Q11: So'm (kursga bog'liq) | R11: 3000 | S11: =IF(Q11="Dollar",R11*kurs_joriy,IF(Q11="So'm (kursga bog'liq)",R11*kurs_joriy/kurs_baza,R11)) -> 3000 | T11: =P11*S11 -> 187730.4 | U11: =T11/kurs_joriy -> 15.692585 | V11: Narx kromkalash xizmati bilan
A12: 8 | B12: Furnitura | C12: Sharnir (mebel petlyasi) 35mm | D12: dona | E12: =SUMIFS(Furnitura!$E$5:$E$400,Furnitura!$B$5:$B$400,E$4,Furnitura!$C$5:$C$400,$C12) -> 30 | F12: =SUMIFS(Furnitura!$E$5:$E$400,Furnitura!$B$5:$B$400,F$4,Furnitura!$C$5:$C$400,$C12) -> 0 | G12: =SUMIFS(Furnitura!$E$5:$E$400,Furnitura!$B$5:$B$400,G$4,Furnitura!$C$5:$C$400,$C12) -> 0 | H12: =SUMIFS(Furnitura!$E$5:$E$400,Furnitura!$B$5:$B$400,H$4,Furnitura!$C$5:$C$400,$C12) -> 0 | I12: =SUMIFS(Furnitura!$E$5:$E$400,Furnitura!$B$5:$B$400,I$4,Furnitura!$C$5:$C$400,$C12) -> 4 | J12: =SUMIFS(Furnitura!$E$5:$E$400,Furnitura!$B$5:$B$400,J$4,Furnitura!$C$5:$C$400,$C12) -> 0 | K12: =SUMIFS(Furnitura!$E$5:$E$400,Furnitura!$B$5:$B$400,K$4,Furnitura!$C$5:$C$400,$C12) -> 0 | L12: =SUMIFS(Furnitura!$E$5:$E$400,Furnitura!$B$5:$B$400,L$4,Furnitura!$C$5:$C$400,$C12) -> 0 | M12: =SUMIFS(Furnitura!$E$5:$E$400,Furnitura!$B$5:$B$400,M$4,Furnitura!$C$5:$C$400,$C12) -> 0 | N12: =SUM(E12:M12) -> 34 | O12: 0 | P12: =N12*(1+O12) -> 34 | Q12: So'm (kursga bog'liq) | R12: 10000 | S12: =IF(Q12="Dollar",R12*kurs_joriy,IF(Q12="So'm (kursga bog'liq)",R12*kurs_joriy/kurs_baza,R12)) -> 10000 | T12: =P12*S12 -> 340000 | U12: =T12/kurs_joriy -> 28.420965
A13: 9 | B13: Furnitura | C13: Ruchka (tutqich) | D13: dona | E13: =SUMIFS(Furnitura!$E$5:$E$400,Furnitura!$B$5:$B$400,E$4,Furnitura!$C$5:$C$400,$C13) -> 6 | F13: =SUMIFS(Furnitura!$E$5:$E$400,Furnitura!$B$5:$B$400,F$4,Furnitura!$C$5:$C$400,$C13) -> 0 | G13: =SUMIFS(Furnitura!$E$5:$E$400,Furnitura!$B$5:$B$400,G$4,Furnitura!$C$5:$C$400,$C13) -> 0 | H13: =SUMIFS(Furnitura!$E$5:$E$400,Furnitura!$B$5:$B$400,H$4,Furnitura!$C$5:$C$400,$C13) -> 2 | I13: =SUMIFS(Furnitura!$E$5:$E$400,Furnitura!$B$5:$B$400,I$4,Furnitura!$C$5:$C$400,$C13) -> 5 | J13: =SUMIFS(Furnitura!$E$5:$E$400,Furnitura!$B$5:$B$400,J$4,Furnitura!$C$5:$C$400,$C13) -> 4 | K13: =SUMIFS(Furnitura!$E$5:$E$400,Furnitura!$B$5:$B$400,K$4,Furnitura!$C$5:$C$400,$C13) -> 0 | L13: =SUMIFS(Furnitura!$E$5:$E$400,Furnitura!$B$5:$B$400,L$4,Furnitura!$C$5:$C$400,$C13) -> 0 | M13: =SUMIFS(Furnitura!$E$5:$E$400,Furnitura!$B$5:$B$400,M$4,Furnitura!$C$5:$C$400,$C13) -> 0 | N13: =SUM(E13:M13) -> 17 | O13: 0 | P13: =N13*(1+O13) -> 17 | Q13: So'm (kursga bog'liq) | R13: 50000 | S13: =IF(Q13="Dollar",R13*kurs_joriy,IF(Q13="So'm (kursga bog'liq)",R13*kurs_joriy/kurs_baza,R13)) -> 50000 | T13: =P13*S13 -> 850000 | U13: =T13/kurs_joriy -> 71.052412
A14: 10 | B14: Furnitura | C14: ="Yashik napravlyayushiysi — Tumbochka ("&tumba_naprav&" mm)" -> Yashik napravlyayushiysi — Tumbochka (350 mm) | D14: juft | E14: =SUMIFS(Furnitura!$E$5:$E$400,Furnitura!$B$5:$B$400,E$4,Furnitura!$C$5:$C$400,$C14) -> 0 | F14: =SUMIFS(Furnitura!$E$5:$E$400,Furnitura!$B$5:$B$400,F$4,Furnitura!$C$5:$C$400,$C14) -> 0 | G14: =SUMIFS(Furnitura!$E$5:$E$400,Furnitura!$B$5:$B$400,G$4,Furnitura!$C$5:$C$400,$C14) -> 0 | H14: =SUMIFS(Furnitura!$E$5:$E$400,Furnitura!$B$5:$B$400,H$4,Furnitura!$C$5:$C$400,$C14) -> 2 | I14: =SUMIFS(Furnitura!$E$5:$E$400,Furnitura!$B$5:$B$400,I$4,Furnitura!$C$5:$C$400,$C14) -> 0 | J14: =SUMIFS(Furnitura!$E$5:$E$400,Furnitura!$B$5:$B$400,J$4,Furnitura!$C$5:$C$400,$C14) -> 0 | K14: =SUMIFS(Furnitura!$E$5:$E$400,Furnitura!$B$5:$B$400,K$4,Furnitura!$C$5:$C$400,$C14) -> 0 | L14: =SUMIFS(Furnitura!$E$5:$E$400,Furnitura!$B$5:$B$400,L$4,Furnitura!$C$5:$C$400,$C14) -> 0 | M14: =SUMIFS(Furnitura!$E$5:$E$400,Furnitura!$B$5:$B$400,M$4,Furnitura!$C$5:$C$400,$C14) -> 0 | N14: =SUM(E14:M14) -> 2 | O14: 0 | P14: =N14*(1+O14) -> 2 | Q14: So'm (kursga bog'liq) | R14: 100000 | S14: =IF(Q14="Dollar",R14*kurs_joriy,IF(Q14="So'm (kursga bog'liq)",R14*kurs_joriy/kurs_baza,R14)) -> 100000 | T14: =P14*S14 -> 200000 | U14: =T14/kurs_joriy -> 16.718214 | V14: Sizning izohingiz: Salaska oddiy bo'lsa 35 000
A15: 11 | B15: Furnitura | C15: ="Yashik napravlyayushiysi — Trimo ("&trimo_naprav&" mm)" -> Yashik napravlyayushiysi — Trimo (400 mm) | D15: juft | E15: =SUMIFS(Furnitura!$E$5:$E$400,Furnitura!$B$5:$B$400,E$4,Furnitura!$C$5:$C$400,$C15) -> 0 | F15: =SUMIFS(Furnitura!$E$5:$E$400,Furnitura!$B$5:$B$400,F$4,Furnitura!$C$5:$C$400,$C15) -> 0 | G15: =SUMIFS(Furnitura!$E$5:$E$400,Furnitura!$B$5:$B$400,G$4,Furnitura!$C$5:$C$400,$C15) -> 0 | H15: =SUMIFS(Furnitura!$E$5:$E$400,Furnitura!$B$5:$B$400,H$4,Furnitura!$C$5:$C$400,$C15) -> 0 | I15: =SUMIFS(Furnitura!$E$5:$E$400,Furnitura!$B$5:$B$400,I$4,Furnitura!$C$5:$C$400,$C15) -> 3 | J15: =SUMIFS(Furnitura!$E$5:$E$400,Furnitura!$B$5:$B$400,J$4,Furnitura!$C$5:$C$400,$C15) -> 0 | K15: =SUMIFS(Furnitura!$E$5:$E$400,Furnitura!$B$5:$B$400,K$4,Furnitura!$C$5:$C$400,$C15) -> 0 | L15: =SUMIFS(Furnitura!$E$5:$E$400,Furnitura!$B$5:$B$400,L$4,Furnitura!$C$5:$C$400,$C15) -> 0 | M15: =SUMIFS(Furnitura!$E$5:$E$400,Furnitura!$B$5:$B$400,M$4,Furnitura!$C$5:$C$400,$C15) -> 0 | N15: =SUM(E15:M15) -> 3 | O15: 0 | P15: =N15*(1+O15) -> 3 | Q15: So'm (kursga bog'liq) | R15: 110000 | S15: =IF(Q15="Dollar",R15*kurs_joriy,IF(Q15="So'm (kursga bog'liq)",R15*kurs_joriy/kurs_baza,R15)) -> 110000 | T15: =P15*S15 -> 330000 | U15: =T15/kurs_joriy -> 27.585054 | V15: Sizning izohingiz: Salaska oddiy bo'lsa 45 000
A16: 12 | B16: Furnitura | C16: ="Yashik napravlyayushiysi — Chester ("&chest_naprav&" mm)" -> Yashik napravlyayushiysi — Chester (450 mm) | D16: juft | E16: =SUMIFS(Furnitura!$E$5:$E$400,Furnitura!$B$5:$B$400,E$4,Furnitura!$C$5:$C$400,$C16) -> 0 | F16: =SUMIFS(Furnitura!$E$5:$E$400,Furnitura!$B$5:$B$400,F$4,Furnitura!$C$5:$C$400,$C16) -> 0 | G16: =SUMIFS(Furnitura!$E$5:$E$400,Furnitura!$B$5:$B$400,G$4,Furnitura!$C$5:$C$400,$C16) -> 0 | H16: =SUMIFS(Furnitura!$E$5:$E$400,Furnitura!$B$5:$B$400,H$4,Furnitura!$C$5:$C$400,$C16) -> 0 | I16: =SUMIFS(Furnitura!$E$5:$E$400,Furnitura!$B$5:$B$400,I$4,Furnitura!$C$5:$C$400,$C16) -> 0 | J16: =SUMIFS(Furnitura!$E$5:$E$400,Furnitura!$B$5:$B$400,J$4,Furnitura!$C$5:$C$400,$C16) -> 4 | K16: =SUMIFS(Furnitura!$E$5:$E$400,Furnitura!$B$5:$B$400,K$4,Furnitura!$C$5:$C$400,$C16) -> 0 | L16: =SUMIFS(Furnitura!$E$5:$E$400,Furnitura!$B$5:$B$400,L$4,Furnitura!$C$5:$C$400,$C16) -> 0 | M16: =SUMIFS(Furnitura!$E$5:$E$400,Furnitura!$B$5:$B$400,M$4,Furnitura!$C$5:$C$400,$C16) -> 0 | N16: =SUM(E16:M16) -> 4 | O16: 0 | P16: =N16*(1+O16) -> 4 | Q16: So'm (kursga bog'liq) | R16: 120000 | S16: =IF(Q16="Dollar",R16*kurs_joriy,IF(Q16="So'm (kursga bog'liq)",R16*kurs_joriy/kurs_baza,R16)) -> 120000 | T16: =P16*S16 -> 480000 | U16: =T16/kurs_joriy -> 40.123715 | V16: Sizning izohingiz: Salaska oddiy bo'lsa 50 000
A17: 13 | B17: Furnitura | C17: Shtanga (kiyim ilgich trubasi) | D17: m | E17: =SUMIFS(Furnitura!$E$5:$E$400,Furnitura!$B$5:$B$400,E$4,Furnitura!$C$5:$C$400,$C17) -> 1.556 | F17: =SUMIFS(Furnitura!$E$5:$E$400,Furnitura!$B$5:$B$400,F$4,Furnitura!$C$5:$C$400,$C17) -> 0 | G17: =SUMIFS(Furnitura!$E$5:$E$400,Furnitura!$B$5:$B$400,G$4,Furnitura!$C$5:$C$400,$C17) -> 0 | H17: =SUMIFS(Furnitura!$E$5:$E$400,Furnitura!$B$5:$B$400,H$4,Furnitura!$C$5:$C$400,$C17) -> 0 | I17: =SUMIFS(Furnitura!$E$5:$E$400,Furnitura!$B$5:$B$400,I$4,Furnitura!$C$5:$C$400,$C17) -> 0 | J17: =SUMIFS(Furnitura!$E$5:$E$400,Furnitura!$B$5:$B$400,J$4,Furnitura!$C$5:$C$400,$C17) -> 0 | K17: =SUMIFS(Furnitura!$E$5:$E$400,Furnitura!$B$5:$B$400,K$4,Furnitura!$C$5:$C$400,$C17) -> 0 | L17: =SUMIFS(Furnitura!$E$5:$E$400,Furnitura!$B$5:$B$400,L$4,Furnitura!$C$5:$C$400,$C17) -> 0 | M17: =SUMIFS(Furnitura!$E$5:$E$400,Furnitura!$B$5:$B$400,M$4,Furnitura!$C$5:$C$400,$C17) -> 0 | N17: =SUM(E17:M17) -> 1.556 | O17: 0 | P17: =N17*(1+O17) -> 1.556 | Q17: So'm (kursga bog'liq) | R17: 30000 | S17: =IF(Q17="Dollar",R17*kurs_joriy,IF(Q17="So'm (kursga bog'liq)",R17*kurs_joriy/kurs_baza,R17)) -> 30000 | T17: =P17*S17 -> 46680 | U17: =T17/kurs_joriy -> 3.9020313
A18: 14 | B18: Furnitura | C18: Shtanga derjateli | D18: dona | E18: =SUMIFS(Furnitura!$E$5:$E$400,Furnitura!$B$5:$B$400,E$4,Furnitura!$C$5:$C$400,$C18) -> 4 | F18: =SUMIFS(Furnitura!$E$5:$E$400,Furnitura!$B$5:$B$400,F$4,Furnitura!$C$5:$C$400,$C18) -> 0 | G18: =SUMIFS(Furnitura!$E$5:$E$400,Furnitura!$B$5:$B$400,G$4,Furnitura!$C$5:$C$400,$C18) -> 0 | H18: =SUMIFS(Furnitura!$E$5:$E$400,Furnitura!$B$5:$B$400,H$4,Furnitura!$C$5:$C$400,$C18) -> 0 | I18: =SUMIFS(Furnitura!$E$5:$E$400,Furnitura!$B$5:$B$400,I$4,Furnitura!$C$5:$C$400,$C18) -> 0 | J18: =SUMIFS(Furnitura!$E$5:$E$400,Furnitura!$B$5:$B$400,J$4,Furnitura!$C$5:$C$400,$C18) -> 0 | K18: =SUMIFS(Furnitura!$E$5:$E$400,Furnitura!$B$5:$B$400,K$4,Furnitura!$C$5:$C$400,$C18) -> 0 | L18: =SUMIFS(Furnitura!$E$5:$E$400,Furnitura!$B$5:$B$400,L$4,Furnitura!$C$5:$C$400,$C18) -> 0 | M18: =SUMIFS(Furnitura!$E$5:$E$400,Furnitura!$B$5:$B$400,M$4,Furnitura!$C$5:$C$400,$C18) -> 0 | N18: =SUM(E18:M18) -> 4 | O18: 0 | P18: =N18*(1+O18) -> 4 | Q18: So'm (kursga bog'liq) | R18: 10000 | S18: =IF(Q18="Dollar",R18*kurs_joriy,IF(Q18="So'm (kursga bog'liq)",R18*kurs_joriy/kurs_baza,R18)) -> 10000 | T18: =P18*S18 -> 40000 | U18: =T18/kurs_joriy -> 3.3436429
A19: 15 | B19: Furnitura | C19: Polka derjateli | D19: dona | E19: =SUMIFS(Furnitura!$E$5:$E$400,Furnitura!$B$5:$B$400,E$4,Furnitura!$C$5:$C$400,$C19) -> 16 | F19: =SUMIFS(Furnitura!$E$5:$E$400,Furnitura!$B$5:$B$400,F$4,Furnitura!$C$5:$C$400,$C19) -> 0 | G19: =SUMIFS(Furnitura!$E$5:$E$400,Furnitura!$B$5:$B$400,G$4,Furnitura!$C$5:$C$400,$C19) -> 0 | H19: =SUMIFS(Furnitura!$E$5:$E$400,Furnitura!$B$5:$B$400,H$4,Furnitura!$C$5:$C$400,$C19) -> 0 | I19: =SUMIFS(Furnitura!$E$5:$E$400,Furnitura!$B$5:$B$400,I$4,Furnitura!$C$5:$C$400,$C19) -> 8 | J19: =SUMIFS(Furnitura!$E$5:$E$400,Furnitura!$B$5:$B$400,J$4,Furnitura!$C$5:$C$400,$C19) -> 0 | K19: =SUMIFS(Furnitura!$E$5:$E$400,Furnitura!$B$5:$B$400,K$4,Furnitura!$C$5:$C$400,$C19) -> 0 | L19: =SUMIFS(Furnitura!$E$5:$E$400,Furnitura!$B$5:$B$400,L$4,Furnitura!$C$5:$C$400,$C19) -> 0 | M19: =SUMIFS(Furnitura!$E$5:$E$400,Furnitura!$B$5:$B$400,M$4,Furnitura!$C$5:$C$400,$C19) -> 0 | N19: =SUM(E19:M19) -> 24 | O19: 0 | P19: =N19*(1+O19) -> 24 | Q19: So'm (kursga bog'liq) | R19: 500 | S19: =IF(Q19="Dollar",R19*kurs_joriy,IF(Q19="So'm (kursga bog'liq)",R19*kurs_joriy/kurs_baza,R19)) -> 500 | T19: =P19*S19 -> 12000 | U19: =T19/kurs_joriy -> 1.0030929
A20: 16 | B20: Furnitura | C20: Konfirmat 7×50 | D20: dona | E20: =SUMIFS(Furnitura!$E$5:$E$400,Furnitura!$B$5:$B$400,E$4,Furnitura!$C$5:$C$400,$C20) -> 48 | F20: =SUMIFS(Furnitura!$E$5:$E$400,Furnitura!$B$5:$B$400,F$4,Furnitura!$C$5:$C$400,$C20) -> 8 | G20: =SUMIFS(Furnitura!$E$5:$E$400,Furnitura!$B$5:$B$400,G$4,Furnitura!$C$5:$C$400,$C20) -> 0 | H20: =SUMIFS(Furnitura!$E$5:$E$400,Furnitura!$B$5:$B$400,H$4,Furnitura!$C$5:$C$400,$C20) -> 20 | I20: =SUMIFS(Furnitura!$E$5:$E$400,Furnitura!$B$5:$B$400,I$4,Furnitura!$C$5:$C$400,$C20) -> 32 | J20: =SUMIFS(Furnitura!$E$5:$E$400,Furnitura!$B$5:$B$400,J$4,Furnitura!$C$5:$C$400,$C20) -> 28 | K20: =SUMIFS(Furnitura!$E$5:$E$400,Furnitura!$B$5:$B$400,K$4,Furnitura!$C$5:$C$400,$C20) -> 8 | L20: =SUMIFS(Furnitura!$E$5:$E$400,Furnitura!$B$5:$B$400,L$4,Furnitura!$C$5:$C$400,$C20) -> 6 | M20: =SUMIFS(Furnitura!$E$5:$E$400,Furnitura!$B$5:$B$400,M$4,Furnitura!$C$5:$C$400,$C20) -> 0 | N20: =SUM(E20:M20) -> 150 | O20: 0 | P20: =N20*(1+O20) -> 150 | Q20: So'm (kursga bog'liq) | R20: 2000 | S20: =IF(Q20="Dollar",R20*kurs_joriy,IF(Q20="So'm (kursga bog'liq)",R20*kurs_joriy/kurs_baza,R20)) -> 2000 | T20: =P20*S20 -> 300000 | U20: =T20/kurs_joriy -> 25.077322 | V20: Sizning izohingiz: x sentrik
A21: 17 | B21: Furnitura | C21: Konfirmat zaglushkasi | D21: dona | E21: =SUMIFS(Furnitura!$E$5:$E$400,Furnitura!$B$5:$B$400,E$4,Furnitura!$C$5:$C$400,$C21) -> 48 | F21: =SUMIFS(Furnitura!$E$5:$E$400,Furnitura!$B$5:$B$400,F$4,Furnitura!$C$5:$C$400,$C21) -> 0 | G21: =SUMIFS(Furnitura!$E$5:$E$400,Furnitura!$B$5:$B$400,G$4,Furnitura!$C$5:$C$400,$C21) -> 0 | H21: =SUMIFS(Furnitura!$E$5:$E$400,Furnitura!$B$5:$B$400,H$4,Furnitura!$C$5:$C$400,$C21) -> 12 | I21: =SUMIFS(Furnitura!$E$5:$E$400,Furnitura!$B$5:$B$400,I$4,Furnitura!$C$5:$C$400,$C21) -> 20 | J21: =SUMIFS(Furnitura!$E$5:$E$400,Furnitura!$B$5:$B$400,J$4,Furnitura!$C$5:$C$400,$C21) -> 12 | K21: =SUMIFS(Furnitura!$E$5:$E$400,Furnitura!$B$5:$B$400,K$4,Furnitura!$C$5:$C$400,$C21) -> 0 | L21: =SUMIFS(Furnitura!$E$5:$E$400,Furnitura!$B$5:$B$400,L$4,Furnitura!$C$5:$C$400,$C21) -> 0 | M21: =SUMIFS(Furnitura!$E$5:$E$400,Furnitura!$B$5:$B$400,M$4,Furnitura!$C$5:$C$400,$C21) -> 0 | N21: =SUM(E21:M21) -> 92 | O21: 0 | P21: =N21*(1+O21) -> 92 | Q21: So'm (kursga bog'liq) | R21: 2000 | S21: =IF(Q21="Dollar",R21*kurs_joriy,IF(Q21="So'm (kursga bog'liq)",R21*kurs_joriy/kurs_baza,R21)) -> 2000 | T21: =P21*S21 -> 184000 | U21: =T21/kurs_joriy -> 15.380757 | V21: Sizning izohingiz: x sentrik
